Workbook

Sheet Plant_Database
A1: Plant_ID | B1: Plant_Name | C1: Plant_Type | D1: Technology | E1: Capacity_MW | F1: Fuel_Cost_EUR_MWh | G1: CO2_Emissions_t_MWh | H1: Fixed_OM_EUR_MW_yr | I1: Variable_OM_EUR_MWh | J1: Availability_Percent
A2: 1 | B2: Lignite_Neurath | C2: Lignite | D2: Coal | E2: 4400 | F2: 5 | G2: 1.1 | H2: 45000 | I2: 4 | J2: 85
A3: 2 | B3: Lignite_Niederaussem | C3: Lignite | D3: Coal | E3: 3864 | F3: 5 | G3: 1.12 | H3: 45000 | I3: 4 | J3: 83
A4: 3 | B4: Lignite_Jaenschwalde | C4: Lignite | D4: Coal | E4: 3000 | F4: 5 | G4: 1.09 | H4: 45000 | I4: 4 | J4: 84
A5: 4 | B5: Lignite_BoxbergII | C5: Lignite | D5: Coal | E5: 2575 | F5: 5 | G5: 1.11 | H5: 45000 | I5: 4 | J5: 86
A6: 5 | B6: HardCoal_Moorburg | C6: Hard Coal | D6: Coal | E6: 4800 | F6: 38 | G6: 0.9 | H6: 40000 | I6: 3.5 | J6: 88
A7: 6 | B7: HardCoal_Datteln | C7: Hard Coal | D7: Coal | E7: 3200 | F7: 40 | G7: 0.92 | H7: 40000 | I7: 3.5 | J7: 86
A8: 7 | B8: HardCoal_Walsum | C8: Hard Coal | D8: Coal | E8: 3500 | F8: 39 | G8: 0.91 | H8: 40000 | I8: 3.5 | J8: 87
A9: 8 | B9: HardCoal_Wilhelmshaven | C9: Hard Coal | D9: Coal | E9: 3200 | F9: 37 | G9: 0.89 | H9: 40000 | I9: 3.5 | J9: 89
A10: 9 | B10: HardCoal_Mehrum | C10: Hard Coal | D10: Coal | E10: 2100 | F10: 38 | G10: 0.9 | H10: 40000 | I10: 3.5 | J10: 85
A11: 10 | B11: HardCoal_Heyden | C11: Hard Coal | D11: Coal | E11: 1200 | F11: 39 | G11: 0.91 | H11: 40000 | I11: 3.5 | J11: 86
A12: 11 | B12: CCGT_Irsching | C12: CCGT | D12: Gas | E12: 3600 | F12: 70 | G12: 0.4 | H12: 25000 | I12: 2.5 | J12: 90
A13: 12 | B13: CCGT_Fortuna | C13: CCGT | D13: Gas | E13: 2300 | F13: 72 | G13: 0.41 | H13: 25000 | I13: 2.5 | J13: 88
... A41: 40 | B41: Biomass_Waste | C41: Biomass | D41: Biomass | E41: 2400 | F41: 48 | G41: 0.08 | H41: 60000 | I41: 4.5 | J41: 82

Sheet Market_Scenarios
A1: Scenario_Name | B1: Demand_MW | C1: Carbon_Price_EUR_ton | D1: Wind_Availability_Percent | E1: Solar_Availability_Percent | F1: Period_Type | G1: Season | H1: Description
A2: Base_Load_Summer | B2: 45000 | C2: 80 | D2: 35 | E2: 25 | F2: Base | G2: Summer | H2: Typical summer midday with moderate demand
A3: Peak_Load_Winter | B3: 65000 | C3: 80 | D3: 45 | E3: 5 | F3: Peak | G3: Winter | H3: Cold winter evening with high heating load
A4: Off_Peak_Spring | B4: 35000 | C4: 80 | D4: 40 | E4: 20 | F4: Off-Peak | G4: Spring | H4: Mild spring morning with low demand
A5: High_Wind_Day | B5: 48000 | C5: 80 | D5: 65 | E5: 15 | F5: Base | G5: Fall | H5: Windy autumn day with high wind generation
A6: Low_Renewable_Day | B6: 52000 | C6: 80 | D6: 15 | E6: 8 | F6: Peak | G6: Winter | H6: Calm winter day with low renewable output
A7: High_Solar_Summer | B7: 42000 | C7: 80 | D7: 30 | E7: 40 | F7: Peak | G7: Summer | H7: Hot summer afternoon with peak solar
A8: Low_Carbon_Price | B8: 48000 | C8: 40 | D8: 35 | E8: 20 | F8: Base | G8: Spring | H8: Same as base but with low carbon price
A9: High_Carbon_Price | B9: 48000 | C9: 120 | D9: 35 | E9: 20 | F9: Base | G9: Spring | H9: Same as base but with high carbon price
A10: Extreme_Peak | B10: 70000 | C10: 80 | D10: 25 | E10: 3 | F10: Peak | G10: Winter | H10: Extreme cold snap with maximum demand
A11: Extreme_Low_Demand | B11: 30000 | C11: 80 | D11: 50 | E11: 30 | F11: Off-Peak | G11: Summer | H11: Warm summer night with minimal demand

Sheet Input_Parameters
A1: SCENARIO INPUTS
A2: SCENARIO SELECTOR
A3: Select Scenario | B3: Peak_Load_Winter
A5: MARKET CONDITIONS
A6: Demand Level (MW): | B6: =_xlfn.XLOOKUP($B$3,Market_Scenarios!$A$2:$A$11,Market_Scenarios!$B$2:$B$11,"Not Found",0) -> 65000
A7: Period: | B7: =_xlfn.XLOOKUP($B$3,Market_Scenarios!$A$2:$A$11,Market_Scenarios!$F$2:$F$11,"Not Found",0) -> Peak
A8: Season: | B8: =_xlfn.XLOOKUP($B$3,Market_Scenarios!$A$2:$A$11,Market_Scenarios!$G$2:$G$11,"Not Found",0) -> Winter
A10: PRICING PARAMETERS
A11: Carbon Price (€/ton): | B11: =_xlfn.XLOOKUP($B$3,Market_Scenarios!$A$2:$A$11,Market_Scenarios!$C$2:$C$11,"Not Found",0) -> 80
A12: Gas Price Multiplier: | B12: 1
A13: Coal Price Multiplier: | B13: 1
A15: RENEWABLE AVAILABILITY
A16: Wind Availability (%): | B16: =_xlfn.XLOOKUP($B$3,Market_Scenarios!$A$2:$A$11,Market_Scenarios!$D$2:$D$11,"Not Found",0) -> 45
A17: Solar Availability (%): | B17: =_xlfn.XLOOKUP($B$3,Market_Scenarios!$A$2:$A$11,Market_Scenarios!$E$2:$E$11,"Not Found",0) -> 5
A19: SCENARIO DESCRIPTION
A20: =_xlfn.XLOOKUP($B$3,Market_Scenarios!$A$2:$A$11,Market_Scenarios!$H$2:$H$11,"Select a scenario",0) -> Cold winter evening with high heating load

Sheet Data_Entry
A1: Plant_Name | B1: Technology | C1: Capacity_MW | D1: Availability_% | E1: Available_Capacity_MW | F1: Fuel_Cost | G1: CO2_Emissions | H1: Carbon_Price | I1: Carbon_Cost | J1: Variable_OM | K1: SRMC(Short Run Marginal Cost) | L1: Cumulative_Capacity | M1: Demand | N1: Dispatched (Yes/No) | O1: Generation_MW | P1: Revenue | Q1: Total Variable Cost | R1: Gross Margin | S1: CO2 Emitted
A2: =Plant_Database!B2 -> Lignite_Neurath | B2: =Plant_Database!D2 -> Coal | C2: =Plant_Database!E2 -> 4400 | D2: =IF(OR(B2="Wind"),Input_Parameters!$B$16,IF(B2="Solar",Input_Parameters!$B$17,Plant_Database!J2)) -> 85 | E2: =C2*(D2/100) -> 3740 | F2: =Plant_Database!F2*IF(B2="Gas",Input_Parameters!$B$12,IF(B2="Coal",Input_Parameters!$B$13,1)) -> 5 | G2: =Plant_Database!G2 -> 1.1 | H2: =Input_Parameters!$B$11 -> 80 | I2: =G2*H2 -> 88 | J2: =Plant_Database!I2 -> 4 | K2: =F2+I2+J2 -> 97 | L2: =SUM($E$2:E2) -> 3740 | M2: =Input_Parameters!$B$6 -> 65000 | N2: =IF(L2 - E2 < $M$2, "Yes", "No") -> Yes | O2: =IF(N2="Yes", MIN(E2, $M$2 - (L2 - E2)), 0) -> 3740 | P2: =O2 * _xlfn.MAXIFS($K$2:$K$100, $N$2:$N$100, "Yes") -> 558756 | Q2: =O2 * K2 -> 362780 | R2: =P2 - Q2 -> 195976 | S2: =O2 * G2 -> 4114
A3: =Plant_Database!B3 -> Lignite_Niederaussem | B3: =Plant_Database!D3 -> Coal | C3: =Plant_Database!E3 -> 3864 | D3: =IF(OR(B3="Wind"),Input_Parameters!$B$16,IF(B3="Solar",Input_Parameters!$B$17,Plant_Database!J3)) -> 83 | E3: =C3*(D3/100) -> 3207.12 | F3: =Plant_Database!F3*IF(B3="Gas",Input_Parameters!$B$12,IF(B3="Coal",Input_Parameters!$B$13,1)) -> 5 | G3: =Plant_Database!G3 -> 1.12 | H3: =Input_Parameters!$B$11 -> 80 | I3: =G3*H3 -> 89.6 | J3: =Plant_Database!I3 -> 4 | K3: =F3+I3+J3 -> 98.6 | L3: =SUM($E$2:E3) -> 6947.12 | M3: =Input_Parameters!$B$6 -> 65000 | N3: =IF(L3 - E3 < $M$2, "Yes", "No") -> Yes | O3: =IF(N3="Yes", MIN(E3, $M$2 - (L3 - E3)), 0) -> 3207.12 | P3: =O3 * _xlfn.MAXIFS($K$2:$K$100, $N$2:$N$100, "Yes") -> 479143.73 | Q3: =O3 * K3 -> 316222.03 | R3: =P3 - Q3 -> 162921.7 | S3: =O3 * G3 -> 3591.9744
A4: =Plant_Database!B4 -> Lignite_Jaenschwalde | B4: =Plant_Database!D4 -> Coal | C4: =Plant_Database!E4 -> 3000 | D4: =IF(OR(B4="Wind"),Input_Parameters!$B$16,IF(B4="Solar",Input_Parameters!$B$17,Plant_Database!J4)) -> 84 | E4: =C4*(D4/100) -> 2520 | F4: =Plant_Database!F4*IF(B4="Gas",Input_Parameters!$B$12,IF(B4="Coal",Input_Parameters!$B$13,1)) -> 5 | G4: =Plant_Database!G4 -> 1.09 | H4: =Input_Parameters!$B$11 -> 80 | I4: =G4*H4 -> 87.2 | J4: =Plant_Database!I4 -> 4 | K4: =F4+I4+J4 -> 96.2 | L4: =SUM($E$2:E4) -> 9467.12 | M4: =Input_Parameters!$B$6 -> 65000 | N4: =IF(L4 - E4 < $M$2, "Yes", "No") -> Yes | O4: =IF(N4="Yes", MIN(E4, $M$2 - (L4 - E4)), 0) -> 2520 | P4: =O4 * _xlfn.MAXIFS($K$2:$K$100, $N$2:$N$100, "Yes") -> 376488 | Q4: =O4 * K4 -> 242424 | R4: =P4 - Q4 -> 134064 | S4: =O4 * G4 -> 2746.8
A5: =Plant_Database!B5 -> Lignite_BoxbergII | B5: =Plant_Database!D5 -> Coal | C5: =Plant_Database!E5 -> 2575 | D5: =IF(OR(B5="Wind"),Input_Parameters!$B$16,IF(B5="Solar",Input_Parameters!$B$17,Plant_Database!J5)) -> 86 | E5: =C5*(D5/100) -> 2214.5 | F5: =Plant_Database!F5*IF(B5="Gas",Input_Parameters!$B$12,IF(B5="Coal",Input_Parameters!$B$13,1)) -> 5 | G5: =Plant_Database!G5 -> 1.11 | H5: =Input_Parameters!$B$11 -> 80 | I5: =G5*H5 -> 88.8 | J5: =Plant_Database!I5 -> 4 | K5: =F5+I5+J5 -> 97.8 | L5: =SUM($E$2:E5) -> 11681.62 | M5: =Input_Parameters!$B$6 -> 65000 | N5: =IF(L5 - E5 < $M$2, "Yes", "No") -> Yes | O5: =IF(N5="Yes", MIN(E5, $M$2 - (L5 - E5)), 0) -> 2214.5 | P5: =O5 * _xlfn.MAXIFS($K$2:$K$100, $N$2:$N$100, "Yes") -> 330846.3 | Q5: =O5 * K5 -> 216578.1 | R5: =P5 - Q5 -> 114268.2 | S5: =O5 * G5 -> 2458.095
A6: =Plant_Database!B6 -> HardCoal_Moorburg | B6: =Plant_Database!D6 -> Coal | C6: =Plant_Database!E6 -> 4800 | D6: =IF(OR(B6="Wind"),Input_Parameters!$B$16,IF(B6="Solar",Input_Parameters!$B$17,Plant_Database!J6)) -> 88 | E6: =C6*(D6/100) -> 4224 | F6: =Plant_Database!F6*IF(B6="Gas",Input_Parameters!$B$12,IF(B6="Coal",Input_Parameters!$B$13,1)) -> 38 | G6: =Plant_Database!G6 -> 0.9 | H6: =Input_Parameters!$B$11 -> 80 | I6: =G6*H6 -> 72 | J6: =Plant_Database!I6 -> 3.5 | K6: =F6+I6+J6 -> 113.5 | L6: =SUM($E$2:E6) -> 15905.62 | M6: =Input_Parameters!$B$6 -> 65000 | N6: =IF(L6 - E6 < $M$2, "Yes", "No") -> Yes | O6: =IF(N6="Yes", MIN(E6, $M$2 - (L6 - E6)), 0) -> 4224 | P6: =O6 * _xlfn.MAXIFS($K$2:$K$100, $N$2:$N$100, "Yes") -> 631065.6 | Q6: =O6 * K6 -> 479424 | R6: =P6 - Q6 -> 151641.6 | S6: =O6 * G6 -> 3801.6
A7: =Plant_Database!B7 -> HardCoal_Datteln | B7: =Plant_Database!D7 -> Coal | C7: =Plant_Database!E7 -> 3200 | D7: =IF(OR(B7="Wind"),Input_Parameters!$B$16,IF(B7="Solar",Input_Parameters!$B$17,Plant_Database!J7)) -> 86 | E7: =C7*(D7/100) -> 2752 | F7: =Plant_Database!F7*IF(B7="Gas",Input_Parameters!$B$12,IF(B7="Coal",Input_Parameters!$B$13,1)) -> 40 | G7: =Plant_Database!G7 -> 0.92 | H7: =Input_Parameters!$B$11 -> 80 | I7: =G7*H7 -> 73.6 | J7: =Plant_Database!I7 -> 3.5 | K7: =F7+I7+J7 -> 117.1 | L7: =SUM($E$2:E7) -> 18657.62 | M7: =Input_Parameters!$B$6 -> 65000 | N7: =IF(L7 - E7 < $M$2, "Yes", "No") -> Yes | O7: =IF(N7="Yes", MIN(E7, $M$2 - (L7 - E7)), 0) -> 2752 | P7: =O7 * _xlfn.MAXIFS($K$2:$K$100, $N$2:$N$100, "Yes") -> 411148.8 | Q7: =O7 * K7 -> 322259.2 | R7: =P7 - Q7 -> 88889.6 | S7: =O7 * G7 -> 2531.84
A8: =Plant_Database!B8 -> HardCoal_Walsum | B8: =Plant_Database!D8 -> Coal | C8: =Plant_Database!E8 -> 3500 | D8: =IF(OR(B8="Wind"),Input_Parameters!$B$16,IF(B8="Solar",Input_Parameters!$B$17,Plant_Database!J8)) -> 87 | E8: =C8*(D8/100) -> 3045 | F8: =Plant_Database!F8*IF(B8="Gas",Input_Parameters!$B$12,IF(B8="Coal",Input_Parameters!$B$13,1)) -> 39 | G8: =Plant_Database!G8 -> 0.91 | H8: =Input_Parameters!$B$11 -> 80 | I8: =G8*H8 -> 72.8 | J8: =Plant_Database!I8 -> 3.5 | K8: =F8+I8+J8 -> 115.3 | L8: =SUM($E$2:E8) -> 21702.62 | M8: =Input_Parameters!$B$6 -> 65000 | N8: =IF(L8 - E8 < $M$2, "Yes", "No") -> Yes | O8: =IF(N8="Yes", MIN(E8, $M$2 - (L8 - E8)), 0) -> 3045 | P8: =O8 * _xlfn.MAXIFS($K$2:$K$100, $N$2:$N$100, "Yes") -> 454923 | Q8: =O8 * K8 -> 351088.5 | R8: =P8 - Q8 -> 103834.5 | S8: =O8 * G8 -> 2770.95
A9: =Plant_Database!B9 -> HardCoal_Wilhelmshaven | B9: =Plant_Database!D9 -> Coal | C9: =Plant_Database!E9 -> 3200 | D9: =IF(OR(B9="Wind"),Input_Parameters!$B$16,IF(B9="Solar",Input_Parameters!$B$17,Plant_Database!J9)) -> 89 | E9: =C9*(D9/100) -> 2848 | F9: =Plant_Database!F9*IF(B9="Gas",Input_Parameters!$B$12,IF(B9="Coal",Input_Parameters!$B$13,1)) -> 37 | G9: =Plant_Database!G9 -> 0.89 | H9: =Input_Parameters!$B$11 -> 80 | I9: =G9*H9 -> 71.2 | J9: =Plant_Database!I9 -> 3.5 | K9: =F9+I9+J9 -> 111.7 | L9: =SUM($E$2:E9) -> 24550.62 | M9: =Input_Parameters!$B$6 -> 65000 | N9: =IF(L9 - E9 < $M$2, "Yes", "No") -> Yes | O9: =IF(N9="Yes", MIN(E9, $M$2 - (L9 - E9)), 0) -> 2848 | P9: =O9 * _xlfn.MAXIFS($K$2:$K$100, $N$2:$N$100, "Yes") -> 425491.2 | Q9: =O9 * K9 -> 318121.6 | R9: =P9 - Q9 -> 107369.6 | S9: =O9 * G9 -> 2534.72
A10: =Plant_Database!B10 -> HardCoal_Mehrum | B10: =Plant_Database!D10 -> Coal | C10: =Plant_Database!E10 -> 2100 | D10: =IF(OR(B10="Wind"),Input_Parameters!$B$16,IF(B10="Solar",Input_Parameters!$B$17,Plant_Database!J10)) -> 85 | E10: =C10*(D10/100) -> 1785 | F10: =Plant_Database!F10*IF(B10="Gas",Input_Parameters!$B$12,IF(B10="Coal",Input_Parameters!$B$13,1)) -> 38 | G10: =Plant_Database!G10 -> 0.9 | H10: =Input_Parameters!$B$11 -> 80 | I10: =G10*H10 -> 72 | J10: =Plant_Database!I10 -> 3.5 | K10: =F10+I10+J10 -> 113.5 | L10: =SUM($E$2:E10) -> 26335.62 | M10: =Input_Parameters!$B$6 -> 65000 | N10: =IF(L10 - E10 < $M$2, "Yes", "No") -> Yes | O10: =IF(N10="Yes", MIN(E10, $M$2 - (L10 - E10)), 0) -> 1785 | P10: =O10 * _xlfn.MAXIFS($K$2:$K$100, $N$2:$N$100, "Yes") -> 266679 | Q10: =O10 * K10 -> 202597.5 | R10: =P10 - Q10 -> 64081.5 | S10: =O10 * G10 -> 1606.5
A11: =Plant_Database!B11 -> HardCoal_Heyden | B11: =Plant_Database!D11 -> Coal | C11: =Plant_Database!E11 -> 1200 | D11: =IF(OR(B11="Wind"),Input_Parameters!$B$16,IF(B11="Solar",Input_Parameters!$B$17,Plant_Database!J11)) -> 86 | E11: =C11*(D11/100) -> 1032 | F11: =Plant_Database!F11*IF(B11="Gas",Input_Parameters!$B$12,IF(B11="Coal",Input_Parameters!$B$13,1)) -> 39 | G11: =Plant_Database!G11 -> 0.91 | H11: =Input_Parameters!$B$11 -> 80 | I11: =G11*H11 -> 72.8 | J11: =Plant_Database!I11 -> 3.5 | K11: =F11+I11+J11 -> 115.3 | L11: =SUM($E$2:E11) -> 27367.62 | M11: =Input_Parameters!$B$6 -> 65000 | N11: =IF(L11 - E11 < $M$2, "Yes", "No") -> Yes | O11: =IF(N11="Yes", MIN(E11, $M$2 - (L11 - E11)), 0) -> 1032 | P11: =O11 * _xlfn.MAXIFS($K$2:$K$100, $N$2:$N$100, "Yes") -> 154180.8 | Q11: =O11 * K11 -> 118989.6 | R11: =P11 - Q11 -> 35191.2 | S11: =O11 * G11 -> 939.12
A12: =Plant_Database!B12 -> CCGT_Irsching | B12: =Plant_Database!D12 -> Gas | C12: =Plant_Database!E12 -> 3600 | D12: =IF(OR(B12="Wind"),Input_Parameters!$B$16,IF(B12="Solar",Input_Parameters!$B$17,Plant_Database!J12)) -> 90 | E12: =C12*(D12/100) -> 3240 | F12: =Plant_Database!F12*IF(B12="Gas",Input_Parameters!$B$12,IF(B12="Coal",Input_Parameters!$B$13,1)) -> 70 | G12: =Plant_Database!G12 -> 0.4 | H12: =Input_Parameters!$B$11 -> 80 | I12: =G12*H12 -> 32 | J12: =Plant_Database!I12 -> 2.5 | K12: =F12+I12+J12 -> 104.5 | L12: =SUM($E$2:E12) -> 30607.62 | M12: =Input_Parameters!$B$6 -> 65000 | N12: =IF(L12 - E12 < $M$2, "Yes", "No") -> Yes | O12: =IF(N12="Yes", MIN(E12, $M$2 - (L12 - E12)), 0) -> 3240 | P12: =O12 * _xlfn.MAXIFS($K$2:$K$100, $N$2:$N$100, "Yes") -> 484056 | Q12: =O12 * K12 -> 338580 | R12: =P12 - Q12 -> 145476 | S12: =O12 * G12 -> 1296
A13: =Plant_Database!B13 -> CCGT_Fortuna | B13: =Plant_Database!D13 -> Gas | C13: =Plant_Database!E13 -> 2300 | D13: =IF(OR(B13="Wind"),Input_Parameters!$B$16,IF(B13="Solar",Input_Parameters!$B$17,Plant_Database!J13)) -> 88 | E13: =C13*(D13/100) -> 2024 | F13: =Plant_Database!F13*IF(B13="Gas",Input_Parameters!$B$12,IF(B13="Coal",Input_Parameters!$B$13,1)) -> 72 | G13: =Plant_Database!G13 -> 0.41 | H13: =Input_Parameters!$B$11 -> 80 | I13: =G13*H13 -> 32.8 | J13: =Plant_Database!I13 -> 2.5 | K13: =F13+I13+J13 -> 107.3 | L13: =SUM($E$2:E13) -> 32631.62 | M13: =Input_Parameters!$B$6 -> 65000 | N13: =IF(L13 - E13 < $M$2, "Yes", "No") -> Yes | O13: =IF(N13="Yes", MIN(E13, $M$2 - (L13 - E13)), 0) -> 2024 | P13: =O13 * _xlfn.MAXIFS($K$2:$K$100, $N$2:$N$100, "Yes") -> 302385.6 | Q13: =O13 * K13 -> 217175.2 | R13: =P13 - Q13 -> 85210.4 | S13: =O13 * G13 -> 829.84
... A41: =Plant_Database!B41 -> Biomass_Waste | B41: =Plant_Database!D41 -> Biomass | C41: =Plant_Database!E41 -> 2400 | D41: =IF(OR(B41="Wind"),Input_Parameters!$B$16,IF(B41="Solar",Input_Parameters!$B$17,Plant_Database!J41)) -> 82 | E41: =C41*(D41/100) -> 1968 | F41: =Plant_Database!F41*IF(B41="Gas",Input_Parameters!$B$12,IF(B41="Coal",Input_Parameters!$B$13,1)) -> 48 | G41: =Plant_Database!G41 -> 0.08 | H41: =Input_Parameters!$B$11 -> 80 | I41: =G41*H41 -> 6.4 | J41: =Plant_Database!I41 -> 4.5 | K41: =F41+I41+J41 -> 58.9 | L41: =SUM($E$2:E41) -> 89238.52 | M41: =Input_Parameters!$B$6 -> 65000 | N41: =IF(L41 - E41 < $M$2, "Yes", "No") -> No | O41: =IF(N41="Yes", MIN(E41, $M$2 - (L41 - E41)), 0) -> 0 | P41: =O41 * _xlfn.MAXIFS($K$2:$K$100, $N$2:$N$100, "Yes") -> 0 | Q41: =O41 * K41 -> 0 | R41: =P41 - Q41 -> 0 | S41: =O41 * G41 -> 0

Sheet Merit_Order
A1: Plant_Name | B1: Technology | C1: Capacity_MW | D1: Availability_% | E1: Available_Capacity_MW | F1: Fuel_Cost | G1: CO2_Emissions | H1: Carbon_Price | I1: Carbon_Cost | J1: Variable_OM | K1: SRMC(Short Run Marginal Cost) | L1: Cumulative_Capacity | M1: Demand | N1: Dispatched (Yes/No) | O1: Generation_MW | P1: Market Price | Q1: Revenue | R1: Total Cost | S1: Gross Margin | T1: CO2 Emitted
A2: {=_xlfn._xlws.SORT(Data_Entry!A2:K100, 11, 1)} -> Solar_South_Bavaria | B2: Solar | C2: 22400 | D2: 5 | E2: 1120 | F2: 0 | G2: 0 | H2: 80 | I2: 0 | J2: 0.2 | K2: 0.2 | L2: =SUM($E$2:E2) -> 1120 | M2: =Input_Parameters!$B$6 -> 65000 | N2: =IF(L2 - E2 < Input_Parameters!$B$6, "Yes", "No") -> Yes | O2: =IF(N2="Yes", MIN(E2, Input_Parameters!$B$6 - (L2 - E2)), 0) -> 1120 | P2: =_xlfn.MAXIFS(K2:K100, N2:N100, "Yes") -> 104.5 | Q2: =O2 * $P$2 -> 117040 | R2: =O2 * K2 -> 224 | S2: =Q2-R2 -> 116816 | T2: =O2 * G2 -> 0
A3: Solar_Southwest | B3: Solar | C3: 20000 | D3: 5 | E3: 1000 | F3: 0 | G3: 0 | H3: 80 | I3: 0 | J3: 0.2 | K3: 0.2 | L3: =SUM($E$2:E3) -> 2120 | M3: =Input_Parameters!$B$6 -> 65000 | N3: =IF(L3 - E3 < Input_Parameters!$B$6, "Yes", "No") -> Yes | O3: =IF(N3="Yes", MIN(E3, Input_Parameters!$B$6 - (L3 - E3)), 0) -> 1000 | P3: =_xlfn.MAXIFS(K3:K101, N3:N101, "Yes") -> 104.5 | Q3: =O3 * $P$2 -> 104500 | R3: =O3 * K3 -> 200 | S3: =Q3-R3 -> 104300 | T3: =O3 * G3 -> 0
A4: Solar_Central | B4: Solar | C4: 17600 | D4: 5 | E4: 880 | F4: 0 | G4: 0 | H4: 80 | I4: 0 | J4: 0.2 | K4: 0.2 | L4: =SUM($E$2:E4) -> 3000 | M4: =Input_Parameters!$B$6 -> 65000 | N4: =IF(L4 - E4 < Input_Parameters!$B$6, "Yes", "No") -> Yes | O4: =IF(N4="Yes", MIN(E4, Input_Parameters!$B$6 - (L4 - E4)), 0) -> 880 | P4: =_xlfn.MAXIFS(K4:K102, N4:N102, "Yes") -> 104.5 | Q4: =O4 * $P$2 -> 91960 | R4: =O4 * K4 -> 176 | S4: =Q4-R4 -> 91784 | T4: =O4 * G4 -> 0
A5: Solar_East | B5: Solar | C5: 16800 | D5: 5 | E5: 840 | F5: 0 | G5: 0 | H5: 80 | I5: 0 | J5: 0.2 | K5: 0.2 | L5: =SUM($E$2:E5) -> 3840 | M5: =Input_Parameters!$B$6 -> 65000 | N5: =IF(L5 - E5 < Input_Parameters!$B$6, "Yes", "No") -> Yes | O5: =IF(N5="Yes", MIN(E5, Input_Parameters!$B$6 - (L5 - E5)), 0) -> 840 | P5: =_xlfn.MAXIFS(K5:K103, N5:N103, "Yes") -> 104.5 | Q5: =O5 * $P$2 -> 87780 | R5: =O5 * K5 -> 168 | S5: =Q5-R5 -> 87612 | T5: =O5 * G5 -> 0
A6: Solar_North | B6: Solar | C6: 15200 | D6: 5 | E6: 760 | F6: 0 | G6: 0 | H6: 80 | I6: 0 | J6: 0.2 | K6: 0.2 | L6: =SUM($E$2:E6) -> 4600 | M6: =Input_Parameters!$B$6 -> 65000 | N6: =IF(L6 - E6 < Input_Parameters!$B$6, "Yes", "No") -> Yes | O6: =IF(N6="Yes", MIN(E6, Input_Parameters!$B$6 - (L6 - E6)), 0) -> 760 | P6: =_xlfn.MAXIFS(K6:K104, N6:N104, "Yes") -> 104.5 | Q6: =O6 * $P$2 -> 79420 | R6: =O6 * K6 -> 152 | S6: =Q6-R6 -> 79268 | T6: =O6 * G6 -> 0
A7: OnshoreWind_North | B7: Wind | C7: 18750 | D7: 45 | E7: 8437.5 | F7: 0 | G7: 0 | H7: 80 | I7: 0 | J7: 0.5 | K7: 0.5 | L7: =SUM($E$2:E7) -> 13037.5 | M7: =Input_Parameters!$B$6 -> 65000 | N7: =IF(L7 - E7 < Input_Parameters!$B$6, "Yes", "No") -> Yes | O7: =IF(N7="Yes", MIN(E7, Input_Parameters!$B$6 - (L7 - E7)), 0) -> 8437.5 | P7: =_xlfn.MAXIFS(K7:K105, N7:N105, "Yes") -> 104.5 | Q7: =O7 * $P$2 -> 881718.75 | R7: =O7 * K7 -> 4218.75 | S7: =Q7-R7 -> 877500 | T7: =O7 * G7 -> 0
A8: OnshoreWind_Central | B8: Wind | C8: 15625 | D8: 45 | E8: 7031.25 | F8: 0 | G8: 0 | H8: 80 | I8: 0 | J8: 0.5 | K8: 0.5 | L8: =SUM($E$2:E8) -> 20068.75 | M8: =Input_Parameters!$B$6 -> 65000 | N8: =IF(L8 - E8 < Input_Parameters!$B$6, "Yes", "No") -> Yes | O8: =IF(N8="Yes", MIN(E8, Input_Parameters!$B$6 - (L8 - E8)), 0) -> 7031.25 | P8: =_xlfn.MAXIFS(K8:K106, N8:N106, "Yes") -> 104.5 | Q8: =O8 * $P$2 -> 734765.62 | R8: =O8 * K8 -> 3515.625 | S8: =Q8-R8 -> 731250 | T8: =O8 * G8 -> 0
A9: OnshoreWind_South | B9: Wind | C9: 12500 | D9: 45 | E9: 5625 | F9: 0 | G9: 0 | H9: 80 | I9: 0 | J9: 0.5 | K9: 0.5 | L9: =SUM($E$2:E9) -> 25693.75 | M9: =Input_Parameters!$B$6 -> 65000 | N9: =IF(L9 - E9 < Input_Parameters!$B$6, "Yes", "No") -> Yes | O9: =IF(N9="Yes", MIN(E9, Input_Parameters!$B$6 - (L9 - E9)), 0) -> 5625 | P9: =_xlfn.MAXIFS(K9:K107, N9:N107, "Yes") -> 104.5 | Q9: =O9 * $P$2 -> 587812.5 | R9: =O9 * K9 -> 2812.5 | S9: =Q9-R9 -> 585000 | T9: =O9 * G9 -> 0
A10: OnshoreWind_East | B10: Wind | C10: 14375 | D10: 45 | E10: 6468.75 | F10: 0 | G10: 0 | H10: 80 | I10: 0 | J10: 0.5 | K10: 0.5 | L10: =SUM($E$2:E10) -> 32162.5 | M10: =Input_Parameters!$B$6 -> 65000 | N10: =IF(L10 - E10 < Input_Parameters!$B$6, "Yes", "No") -> Yes | O10: =IF(N10="Yes", MIN(E10, Input_Parameters!$B$6 - (L10 - E10)), 0) -> 6468.75 | P10: =_xlfn.MAXIFS(K10:K108, N10:N108, "Yes") -> 104.5 | Q10: =O10 * $P$2 -> 675984.38 | R10: =O10 * K10 -> 3234.375 | S10: =Q10-R10 -> 672750 | T10: =O10 * G10 -> 0
A11: OffshoreWind_NorthSea1 | B11: Wind | C11: 2592 | D11: 45 | E11: 1166.4 | F11: 0 | G11: 0 | H11: 80 | I11: 0 | J11: 1 | K11: 1 | L11: =SUM($E$2:E11) -> 33328.9 | M11: =Input_Parameters!$B$6 -> 65000 | N11: =IF(L11 - E11 < Input_Parameters!$B$6, "Yes", "No") -> Yes | O11: =IF(N11="Yes", MIN(E11, Input_Parameters!$B$6 - (L11 - E11)), 0) -> 1166.4 | P11: =_xlfn.MAXIFS(K11:K109, N11:N109, "Yes") -> 104.5 | Q11: =O11 * $P$2 -> 121888.8 | R11: =O11 * K11 -> 1166.4 | S11: =Q11-R11 -> 120722.4 | T11: =O11 * G11 -> 0
A12: OffshoreWind_NorthSea2 | B12: Wind | C12: 2268 | D12: 45 | E12: 1020.6 | F12: 0 | G12: 0 | H12: 80 | I12: 0 | J12: 1 | K12: 1 | L12: =SUM($E$2:E12) -> 34349.5 | M12: =Input_Parameters!$B$6 -> 65000 | N12: =IF(L12 - E12 < Input_Parameters!$B$6, "Yes", "No") -> Yes | O12: =IF(N12="Yes", MIN(E12, Input_Parameters!$B$6 - (L12 - E12)), 0) -> 1020.6 | P12: =_xlfn.MAXIFS(K12:K110, N12:N110, "Yes") -> 104.5 | Q12: =O12 * $P$2 -> 106652.7 | R12: =O12 * K12 -> 1020.6 | S12: =Q12-R12 -> 105632.1 | T12: =O12 * G12 -> 0
A13: OffshoreWind_Baltic1 | B13: Wind | C13: 1944 | D13: 45 | E13: 874.8 | F13: 0 | G13: 0 | H13: 80 | I13: 0 | J13: 1 | K13: 1 | L13: =SUM($E$2:E13) -> 35224.3 | M13: =Input_Parameters!$B$6 -> 65000 | N13: =IF(L13 - E13 < Input_Parameters!$B$6, "Yes", "No") -> Yes | O13: =IF(N13="Yes", MIN(E13, Input_Parameters!$B$6 - (L13 - E13)), 0) -> 874.8 | P13: =_xlfn.MAXIFS(K13:K111, N13:N111, "Yes") -> 104.5 | Q13: =O13 * $P$2 -> 91416.6 | R13: =O13 * K13 -> 874.8 | S13: =Q13-R13 -> 90541.8 | T13: =O13 * G13 -> 0
A14: OffshoreWind_Baltic2 | B14: Wind | C14: 1728 | D14: 45 | E14: 777.6 | F14: 0 | G14: 0 | H14: 80 | I14: 0 | J14: 1 | K14: 1 | L14: =SUM($E$2:E14) -> 36001.9 | M14: =Input_Parameters!$B$6 -> 65000 | N14: =IF(L14 - E14 < Input_Parameters!$B$6, "Yes", "No") -> Yes | O14: =IF(N14="Yes", MIN(E14, Input_Parameters!$B$6 - (L14 - E14)), 0) -> 777.6 | P14: =_xlfn.MAXIFS(K14:K112, N14:N112, "Yes") -> 104.5 | Q14: =O14 * $P$2 -> 81259.2 | R14: =O14 * K14 -> 777.6 | S14: =Q14-R14 -> 80481.6 | T14: =O14 * G14 -> 0
... A41: OCGT_Grid_Stabilization | B41: Gas Peaker | C41: 1500 | D41: 93 | E41: 1395 | F41: 100 | G41: 0.58 | H41: 80 | I41: 46.4 | J41: 3 | K41: 149.4 | L41: =SUM($E$2:E41) -> 89238.52 | M41: =Input_Parameters!$B$6 -> 65000 | N41: =IF(L41 - E41 < Input_Parameters!$B$6, "Yes", "No") -> No | O41: =IF(N41="Yes", MIN(E41, Input_Parameters!$B$6 - (L41 - E41)), 0) -> 0 | P41: =_xlfn.MAXIFS(K41:K139, N41:N139, "Yes") -> 0 | Q41: =O41 * $P$2 -> 0 | R41: =O41 * K41 -> 0 | S41: =Q41-R41 -> 0 | T41: =O41 * G41 -> 0
A42: 0 | B42: 0 | C42: 0 | D42: 0 | E42: 0 | F42: 0 | G42: 0 | H42: 0 | I42: 0 | J42: 0 | K42: 0
A43: 0 | B43: 0 | C43: 0 | D43: 0 | E43: 0 | F43: 0 | G43: 0 | H43: 0 | I43: 0 | J43: 0 | K43: 0
A44: 0 | B44: 0 | C44: 0 | D44: 0 | E44: 0 | F44: 0 | G44: 0 | H44: 0 | I44: 0 | J44: 0 | K44: 0
A45: 0 | B45: 0 | C45: 0 | D45: 0 | E45: 0 | F45: 0 | G45: 0 | H45: 0 | I45: 0 | J45: 0 | K45: 0
A46: 0 | B46: 0 | C46: 0 | D46: 0 | E46: 0 | F46: 0 | G46: 0 | H46: 0 | I46: 0 | J46: 0 | K46: 0
A47: 0 | B47: 0 | C47: 0 | D47: 0 | E47: 0 | F47: 0 | G47: 0 | H47: 0 | I47: 0 | J47: 0 | K47: 0
A48: 0 | B48: 0 | C48: 0 | D48: 0 | E48: 0 | F48: 0 | G48: 0 | H48: 0 | I48: 0 | J48: 0 | K48: 0
A49: 0 | B49: 0 | C49: 0 | D49: 0 | E49: 0 | F49: 0 | G49: 0 | H49: 0 | I49: 0 | J49: 0 | K49: 0
A50: 0 | B50: 0 | C50: 0 | D50: 0 | E50: 0 | F50: 0 | G50: 0 | H50: 0 | I50: 0 | J50: 0 | K50: 0
A51: 0 | B51: 0 | C51: 0 | D51: 0 | E51: 0 | F51: 0 | G51: 0 | H51: 0 | I51: 0 | J51: 0 | K51: 0
A52: 0 | B52: 0 | C52: 0 | D52: 0 | E52: 0 | F52: 0 | G52: 0 | H52: 0 | I52: 0 | J52: 0 | K52: 0
A53: 0 | B53: 0 | C53: 0 | D53: 0 | E53: 0 | F53: 0 | G53: 0 | H53: 0 | I53: 0 | J53: 0 | K53: 0
... A100: 0 | B100: 0 | C100: 0 | D100: 0 | E100: 0 | F100: 0 | G100: 0 | H100: 0 | I100: 0 | J100: 0 | K100: 0

Sheet Results_Dashboard
A1: POWER MARKET RESULTS DASHBOARD
A2: European Electricity Market Analysis
A3: =CONCATENATE("Current Scenario: ", Input_Parameters!B3) -> Current Scenario: Peak_Load_Winter
A5: Market Clearing Price | C5: Demand Met | E5: Total CO₂ Emissions | G5: Reserve Margin | I5: Renewable Share | K5: System Gross Margin
A6: =IFERROR(_xlfn.MAXIFS(Merit_Order!$K$2:$K$41,Merit_Order!$N$2:$N$41,"Yes"),"N/A") -> 104.5 | C6: =SUM(Merit_Order!$O$2:$O$41) -> 65000 | E6: =SUM(Merit_Order!$T$2:$T$41) -> 16440.411 | G6: =SUM(Merit_Order!$E$2:$E$41)-Input_Parameters!$B$6 -> 24238.52 | I6: {=SUM(SUMIFS(Merit_Order!$O$2:$O$41, Merit_Order!$B$2:$B$41, {"Solar","Wind","Hydro","Biomass"})) / SUM(Merit_Order!$O$2:$O$41)} -> 0.70932154 | K6: =SUM(Merit_Order!$S$2:$S$41) -> 4450501.1
A7: /MWh | C7: MW | E7: tons | G7: MW | I7: % of generation | K7: € (Producer Surplus)
A8: ="Set by " & INDEX(Merit_Order!$B$2:$B$41,MATCH(0,Merit_Order!$S$2:$S$41,0)) -> Set by Gas | C8: =IF(C6=Input_Parameters!$B$6,"✓ Balanced","⚠ Unbalanced") -> ✓ Balanced | E8: =ROUND((E6*1000000)/(C6*1000),1) & " g/kWh" -> 252.9 g/kWh | G8: =TEXT(G6/Input_Parameters!$B$6,"0.0%") & " of demand" -> 37.3% of demand | I8: =TEXT(1-I6,"0.0%") & " fossil" -> 29.1% fossil | K8: ="Revenue: €" & TEXT(SUM(Merit_Order!Q:Q)/1000,"#,##0k") -> Revenue: €6,793k
A10: GENERATION MIX ANALYSIS
A11: Technology | B11: Generation (MW) | C11: Share (%) | D11: Revenue (€) | E11: Gross Margin (€)
A12: Solar | B12: =IF(SUMIFS(Merit_Order!$O$2:$O$41,Merit_Order!$B$2:$B$41,"Solar")=0, NA(), SUMIFS(Merit_Order!$O$2:$O$41,Merit_Order!$B$2:$B$41,"Solar")) -> 4600 | C12: =B12/$B$21 -> 0.070769231 | D12: =SUMIFS(Merit_Order!$Q$2:$Q$41,Merit_Order!$B$2:$B$41,"Solar") -> 480700 | E12: =SUMIFS(Merit_Order!$S$2:$S$41,Merit_Order!$B$2:$B$41,"Solar") -> 479780
A13: Wind | B13: =SUMIFS(Merit_Order!$O$2:$O$41,Merit_Order!$B$2:$B$41,"Wind") -> 31401.9 | C13: =B13/$B$21 -> 0.48310615 | D13: =SUMIFS(Merit_Order!$Q$2:$Q$41,Merit_Order!$B$2:$B$41,"Wind") -> 3281498.6 | E13: =SUMIFS(Merit_Order!$S$2:$S$41,Merit_Order!$B$2:$B$41,"Wind") -> 3263877.9
A14: Hydro | B14: =SUMIFS(Merit_Order!$O$2:$O$41,Merit_Order!$B$2:$B$41,"Hydro") -> 3392 | C14: =B14/$B$21 -> 0.052184615 | D14: =SUMIFS(Merit_Order!$Q$2:$Q$41,Merit_Order!$B$2:$B$41,"Hydro") -> 354464 | E14: =SUMIFS(Merit_Order!$S$2:$S$41,Merit_Order!$B$2:$B$41,"Hydro") -> 335688
A15: Biomass | B15: =SUMIFS(Merit_Order!$O$2:$O$41,Merit_Order!$B$2:$B$41,"Biomass") -> 6712 | C15: =B15/$B$21 -> 0.10326154 | D15: =SUMIFS(Merit_Order!$Q$2:$Q$41,Merit_Order!$B$2:$B$41,"Biomass") -> 701404 | E15: =SUMIFS(Merit_Order!$S$2:$S$41,Merit_Order!$B$2:$B$41,"Biomass") -> 281126.4
A16: Coal | B16: =SUMIFS(Merit_Order!$O$2:$O$41,Merit_Order!$B$2:$B$41,"Coal") -> 11681.62 | C16: =B16/$B$21 -> 0.17971723 | D16: =SUMIFS(Merit_Order!$Q$2:$Q$41,Merit_Order!$B$2:$B$41,"Coal") -> 1220729.3 | E16: =SUMIFS(Merit_Order!$S$2:$S$41,Merit_Order!$B$2:$B$41,"Coal") -> 82725.158
A17: Gas | B17: =SUMIFS(Merit_Order!$O$2:$O$41,Merit_Order!$B$2:$B$41,"Gas") -> 7212.48 | C17: =B17/$B$21 -> 0.11096123 | D17: =SUMIFS(Merit_Order!$Q$2:$Q$41,Merit_Order!$B$2:$B$41,"Gas") -> 753704.16 | E17: =SUMIFS(Merit_Order!$S$2:$S$41,Merit_Order!$B$2:$B$41,"Gas") -> 7303.6
A18: Gas Peaker | B18: =SUMIFS(Merit_Order!$O$2:$O$41,Merit_Order!$B$2:$B$41,"Gas Peaker") -> 0 | C18: =B18/$B$21 -> 0 | D18: =SUMIFS(Merit_Order!$Q$2:$Q$41,Merit_Order!$B$2:$B$41,"Gas Peaker") -> 0 | E18: =SUMIFS(Merit_Order!$S$2:$S$41,Merit_Order!$B$2:$B$41,"Gas Peaker") -> 0
A19: Nuclear | B19: =SUMIFS(Merit_Order!$O$2:$O$41,Merit_Order!$B$2:$B$41,"Nuclear") -> 0 | C19: =B19/$B$21 -> 0 | D19: =SUMIFS(Merit_Order!$Q$2:$Q$41,Merit_Order!$B$2:$B$41,"Nuclear") -> 0 | E19: =SUMIFS(Merit_Order!$S$2:$S$41,Merit_Order!$B$2:$B$41,"Nuclear") -> 0
A21: TOTAL | B21: =SUM(B12:B19) -> 65000 | C21: =SUM(C12:C19) -> 1 | D21: =SUM(D12:D19) -> 6792500 | E21: =SUM(E12:E19) -> 4450501.1
A23: ENVIRONMENTAL IMPACT METRICS
A24: Grid Carbon Intensity | B24: =(SUM(Merit_Order!$T$2:$T$41)*1000000)/(SUM(Merit_Order!$O$2:$O$41)*1000) -> 252.92941 | C24: Benchmark: | D24: =IF(B24<350,"✓ Below EU Target","⚠ Above Target") -> ✓ Below EU Target
A25: Total CO₂ Emissions | B25: =SUM(Merit_Order!$T$2:$T$41) -> 16440.411 | C25: CO₂ Cost Impact: | D25: =SUMPRODUCT(Merit_Order!$I$2:$I$41,Merit_Order!$O$2:$O$41) -> 1315232.9
A26: Renewable Generation | B26: =SUMIFS(Merit_Order!$O$2:$O$41,Merit_Order!$B$2:$B$41,"Solar")+SUMIFS(Merit_Order!$O$2:$O$41,Merit_Order!$B$2:$B$41,"Wind")+SUMIFS(Merit_Order!$O$2:$O$41,Merit_Order!$B$2:$B$41,"Hydro")+SUMIFS(Merit_Order!$O$2:$O$41,Merit_Order!$B$2:$B$41,"Biomass") -> 46105.9 | C26: Share: | D26: =B26/SUM(Merit_Order!$O$2:$O$41) -> 0.70932154
A27: Fossil Fuel Generation | B27: =SUMIFS(Merit_Order!$O$2:$O$41,Merit_Order!$B$2:$B$41,"Coal")+SUMIFS(Merit_Order!$O$2:$O$41,Merit_Order!$B$2:$B$41,"Gas")+SUMIFS(Merit_Order!$O$2:$O$41,Merit_Order!$B$2:$B$41,"Gas Peaker") -> 18894.1 | C27: Share: | D27: =B27/SUM(Merit_Order!$O$2:$O$41) -> 0.29067846
A28: Renewable Curtailment | B28: =(SUMIFS(Merit_Order!$E$2:$E$41,Merit_Order!$B$2:$B$41,"Solar")+SUMIFS(Merit_Order!$E$2:$E$41,Merit_Order!$B$2:$B$41,"Wind"))-(SUMIFS(Merit_Order!$O$2:$O$41,Merit_Order!$B$2:$B$41,"Solar")+SUMIFS(Merit_Order!$O$2:$O$41,Merit_Order!$B$2:$B$41,"Wind")) -> 0 | C28: Curtailment Rate: | D28: =B28/(SUMIFS(Merit_Order!$E$2:$E$41,Merit_Order!$B$2:$B$41,"Solar")+SUMIFS(Merit_Order!$E$2:$E$41,Merit_Order!$B$2:$B$41,"Wind")) -> 0
A30: ECONOMIC & FINANCIAL ANALYSIS
A31: Total Market Revenue | B31: =SUM(Merit_Order!$Q$2:$Q$41) -> 6792500 | C31: (All generators) | E31: Marginal Plant Details
A32: Total System Variable Cost | B32: =SUM(Merit_Order!$R$2:$R$41) -> 2341998.9 | C32: (Production cost) | E32: Technology: | G32: =INDEX(Merit_Order!$B$2:$B$41,MATCH(0,Merit_Order!$S$2:$S$41,0)) -> Gas
A33: System Gross Margin | B33: =SUM(Merit_Order!$S$2:$S$41) -> 4450501.1 | C33: (Producer surplus) | E33: Plant Name: | G33: =INDEX(Merit_Order!$A$2:$A$41,MATCH(0,Merit_Order!$S$2:$S$41,0)) -> CCGT_Irsching
A34: Average Production Cost | B34: =B32/SUM(Merit_Order!$O$2:$O$41) -> 36.030753 | C34: (System efficiency) | E34: SRMC: | G34: =INDEX(Merit_Order!$K$2:$K$41,MATCH(0,Merit_Order!$S$2:$S$41,0)) -> 104.5
A35: Price-Cost Spread | B35: =_xlfn.MAXIFS(Merit_Order!$K$2:$K$41,Merit_Order!$N$2:$N$41,"Yes")-B34 -> 68.469247 | C35: (Market profitability) | E35: Generation: | G35: =INDEX(Merit_Order!$O$2:$O$41,MATCH(0,Merit_Order!$S$2:$S$41,0)) -> 3240
A36: System ROI | B36: =(B31-B32)/B32 -> 1.9003002 | C36: (Return on variable cost) | E36: Sets market price for all generators
A38: CAPACITY & RELIABILITY METRICS
A39: Technology | B39: Installed (MW) | C39: Available (MW) | D39: Dispatched (MW) | E39: Utilization (%) | F39: Full Load Hours/yr
A40: Solar | B40: =SUMIFS(Merit_Order!$C$2:$C$41,Merit_Order!$B$2:$B$41,"Solar") -> 92000 | C40: =SUMIFS(Merit_Order!$E$2:$E$41,Merit_Order!$B$2:$B$41,"Solar") -> 4600 | D40: =SUMIFS(Merit_Order!$O$2:$O$41,Merit_Order!$B$2:$B$41,"Solar") -> 4600 | E40: =D40/C40 -> 1 | F40: =(D40/B40)*8760 -> 438
A41: Wind | B41: =SUMIFS(Merit_Order!$C$2:$C$41,Merit_Order!$B$2:$B$41,"Wind") -> 69782 | C41: =SUMIFS(Merit_Order!$E$2:$E$41,Merit_Order!$B$2:$B$41,"Wind") -> 31401.9 | D41: =SUMIFS(Merit_Order!$O$2:$O$41,Merit_Order!$B$2:$B$41,"Wind") -> 31401.9 | E41: =D41/C41 -> 1 | F41: =(D41/B41)*8760 -> 3942
A42: Hydro | B42: =SUMIFS(Merit_Order!$C$2:$C$41,Merit_Order!$B$2:$B$41,"Hydro") -> 6800 | C42: =SUMIFS(Merit_Order!$E$2:$E$41,Merit_Order!$B$2:$B$41,"Hydro") -> 3392 | D42: =SUMIFS(Merit_Order!$O$2:$O$41,Merit_Order!$B$2:$B$41,"Hydro") -> 3392 | E42: =D42/C42 -> 1 | F42: =(D42/B42)*8760 -> 4369.6941
A43: Biomass | B43: =SUMIFS(Merit_Order!$C$2:$C$41,Merit_Order!$B$2:$B$41,"Biomass") -> 8400 | C43: =SUMIFS(Merit_Order!$E$2:$E$41,Merit_Order!$B$2:$B$41,"Biomass") -> 6712 | D43: =SUMIFS(Merit_Order!$O$2:$O$41,Merit_Order!$B$2:$B$41,"Biomass") -> 6712 | E43: =D43/C43 -> 1 | F43: =(D43/B43)*8760 -> 6999.6571
A44: Coal | B44: =SUMIFS(Merit_Order!$C$2:$C$41,Merit_Order!$B$2:$B$41,"Coal") -> 31839 | C44: =SUMIFS(Merit_Order!$E$2:$E$41,Merit_Order!$B$2:$B$41,"Coal") -> 27367.62 | D44: =SUMIFS(Merit_Order!$O$2:$O$41,Merit_Order!$B$2:$B$41,"Coal") -> 11681.62 | E44: =D44/C44 -> 0.42684092 | F44: =(D44/B44)*8760 -> 3214.014
A45: Gas | B45: =SUMIFS(Merit_Order!$C$2:$C$41,Merit_Order!$B$2:$B$41,"Gas") -> 13020 | C45: =SUMIFS(Merit_Order!$E$2:$E$41,Merit_Order!$B$2:$B$41,"Gas") -> 11638 | D45: =SUMIFS(Merit_Order!$O$2:$O$41,Merit_Order!$B$2:$B$41,"Gas") -> 7212.48 | E45: =D45/C45 -> 0.61973535 | F45: =(D45/B45)*8760 -> 4852.6363
A46: Gas Peaker | B46: =SUMIFS(Merit_Order!$C$2:$C$41,Merit_Order!$B$2:$B$41,"Gas Peaker") -> 4500 | C46: =SUMIFS(Merit_Order!$E$2:$E$41,Merit_Order!$B$2:$B$41,"Gas Peaker") -> 4127 | D46: =SUMIFS(Merit_Order!$O$2:$O$41,Merit_Order!$B$2:$B$41,"Gas Peaker") -> 0 | E46: =D46/C46 -> 0 | F46: =(D46/B46)*8760 -> 0
...
